Workbook

Sheet Assumptions
B4: Quarter Index Reference
C5: Q1'27 | D5: Q2'27 | E5: Q3'27 | F5: Q4'27 | G5: Q1'28 | H5: Q2'28 | I5: Q3'28 | J5: Q4'28 | K5: Q1'29 | L5: Q2'29 | M5: Q3'29 | N5: Q4'29 | O5: Q1'30 | P5: Q2'30 | Q5: Q3'30 | R5: Q4'30 | S5: Q1'31 | T5: Q2'31 | U5: Q3'31 | V5: Q4'31
C6: 1 | D6: 2 | E6: 3 | F6: 4 | G6: 5 | H6: 6 | I6: 7 | J6: 8 | K6: 9 | L6: 10 | M6: 11 | N6: 12 | O6: 13 | P6: 14 | Q6: 15 | R6: 16 | S6: 17 | T6: 18 | U6: 19 | V6: 20
B8: Anchor Distribution Partners
C9: Partner 1 Atlas | D9: Partner 2 Titan | E9: Partner 3 Apex | F9: Partner 4 Vanguard | G9: Partner 5 Nimble
B10: Number of Zones | C10: 6 | D10: 4 | E10: 5 | F10: 3 | G10: 2
B11: Planning Start Quarter | C11: Q2'27 | D11: Q3'27 | E11: Q4'27 | F11: Q1'28 | G11: Q2'28
B12: Go-Live Quarter | C12: Q4'27 | D12: Q1'28 | E12: Q2'28 | F12: Q3'28 | G12: Q4'28
B13: License Activation Quarter | C13: Q2'29 | D13: Q1'29 | E13: Q2'29 | F13: Q3'29 | G13: Q4'29
B14: Implementation MSRP | C14: =C10*$C$17 -> 2100000 | D14: =D10*$C$17 -> 1400000 | E14: =E10*$C$17 -> 1750000 | F14: =F10*$C$17 -> 1050000 | G14: =G10*$C$17 -> 700000
B15: Annual Licensing Fee | C15: =C10*$C$18 -> 510000 | D15: =D10*$C$18 -> 340000 | E15: =E10*$C$18 -> 425000 | F15: =F10*$C$18 -> 255000 | G15: =G10*$C$18 -> 170000
B17: Per-Zone Implementation MSRP | C17: 350000
B18: Per-Zone Annual License | C18: 85000
B19: Total Anchor Zones | C19: =C10+D10+E10+F10+G10 -> 20
B20: Total Implementation Revenue | C20: =C14+D14+E14+F14+G14 -> 7000000
B21: Total Annual Licensing | C21: =C15+D15+E15+F15+G15 -> 1700000
B23: Implementation Payment Terms | C23: 40/35/25
B24: % at Signing | C24: 0.4
B25: % at Go-Live | C25: 0.35
B26: % at Month 12 | C26: 0.25
B28: Zone Go-Live Ramp
C29: Q1'27 | D29: Q2'27 | E29: Q3'27 | F29: Q4'27 | G29: Q1'28 | H29: Q2'28 | I29: Q3'28 | J29: Q4'28
B30: Partner 1 Atlas | C30: 0 | D30: 0 | E30: 0 | F30: 3 | G30: 3 | H30: 0 | I30: 0 | J30: 0
B31: Partner 2 Titan | C31: 0 | D31: 0 | E31: 0 | F31: 0 | G31: 2 | H31: 2 | I31: 0 | J31: 0
B32: Partner 3 Apex | C32: 0 | D32: 0 | E32: 0 | F32: 0 | G32: 0 | H32: 2 | I32: 3 | J32: 0
B33: Partner 4 Vanguard | C33: 0 | D33: 0 | E33: 0 | F33: 0 | G33: 0 | H33: 0 | I33: 2 | J33: 1
B34: Partner 5 Nimble | C34: 0 | D34: 0 | E34: 0 | F34: 0 | G34: 0 | H34: 0 | I34: 0 | J34: 2
B35: Total Zones Going Live | C35: =C30+C31+C32+C33+C34 -> 0 | D35: =D30+D31+D32+D33+D34 -> 0 | E35: =E30+E31+E32+E33+E34 -> 0 | F35: =F30+F31+F32+F33+F34 -> 3 | G35: =G30+G31+G32+G33+G34 -> 5 | H35: =H30+H31+H32+H33+H34 -> 4 | I35: =I30+I31+I32+I33+I34 -> 5 | J35: =J30+J31+J32+J33+J34 -> 3
B36: Cumulative Zones Live | C36: =C35 -> 0 | D36: =C36+D35 -> 0 | E36: =D36+E35 -> 0 | F36: =E36+F35 -> 3 | G36: =F36+G35 -> 8 | H36: =G36+H35 -> 12 | I36: =H36+I35 -> 17 | J36: =I36+J35 -> 20
B38: Quarter Index Lookups
B39: Planning Start Index | C39: =MATCH(C11,$C$5:$V$5,0) -> 2 | D39: =MATCH(D11,$C$5:$V$5,0) -> 3 | E39: =MATCH(E11,$C$5:$V$5,0) -> 4 | F39: =MATCH(F11,$C$5:$V$5,0) -> 5 | G39: =MATCH(G11,$C$5:$V$5,0) -> 6
B40: Go-Live Index | C40: =MATCH(C12,$C$5:$V$5,0) -> 4 | D40: =MATCH(D12,$C$5:$V$5,0) -> 5 | E40: =MATCH(E12,$C$5:$V$5,0) -> 6 | F40: =MATCH(F12,$C$5:$V$5,0) -> 7 | G40: =MATCH(G12,$C$5:$V$5,0) -> 8
B41: License Activation Index | C41: =MATCH(C13,$C$5:$V$5,0) -> 10 | D41: =MATCH(D13,$C$5:$V$5,0) -> 9 | E41: =MATCH(E13,$C$5:$V$5,0) -> 10 | F41: =MATCH(F13,$C$5:$V$5,0) -> 11 | G41: =MATCH(G13,$C$5:$V$5,0) -> 12
B43: Expansion Customer Pricing
B44: Implementation Fee (per zone) | C44: 30000
B45: Program Consulting Fee (per partner) | C45: 75000
B46: Annual Subscription (per zone/year) | C46: 95000
B47: Planning + Implementation (months) | C47: 8
B48: Implementation to Go-Live (quarters) | C48: =ROUNDUP(C47/3,0) -> 3
B50: See 'Pipeline Assumptions' tab
...

Sheet Pipeline Assumptions
B1: Expansion New Partner Pipeline
C3: Q1'27 | D3: Q2'27 | E3: Q3'27 | F3: Q4'27 | G3: Q1'28 | H3: Q2'28 | I3: Q3'28 | J3: Q4'28 | K3: Q1'29 | L3: Q2'29 | M3: Q3'29 | N3: Q4'29 | O3: Q1'30 | P3: Q2'30 | Q3: Q3'30 | R3: Q4'30 | S3: Q1'31 | T3: Q2'31 | U3: Q3'31 | V3: Q4'31
C4: 1 | D4: 2 | E4: 3 | F4: 4 | G4: 5 | H4: 6 | I4: 7 | J4: 8 | K4: 9 | L4: 10 | M4: 11 | N4: 12 | O4: 13 | P4: 14 | Q4: 15 | R4: 16 | S4: 17 | T4: 18 | U4: 19 | V4: 20
B6: New Partners Signed | C6: 0 | D6: 0 | E6: 0 | F6: 0 | G6: 0 | H6: 0 | I6: 0 | J6: 0 | K6: 1 | L6: 2 | M6: 2 | N6: 3 | O6: 4 | P6: 3 | Q6: 4 | R6: 4 | S6: 5 | T6: 4 | U6: 6 | V6: 5
B7: Avg Zones per Partner | C7: 3
B8: New Zones This Quarter | C8: =C6*$C$7 -> 0 | D8: =D6*$C$7 -> 0 | E8: =E6*$C$7 -> 0 | F8: =F6*$C$7 -> 0 | G8: =G6*$C$7 -> 0 | H8: =H6*$C$7 -> 0 | I8: =I6*$C$7 -> 0 | J8: =J6*$C$7 -> 0 | ... V8: =V6*$C$7 -> 15
B9: Cumulative New Zones | C9: =C8 -> 0 | D9: =C9+D8 -> 0 | E9: =D9+E8 -> 0 | F9: =E9+F8 -> 0 | G9: =F9+G8 -> 0 | H9: =G9+H8 -> 0 | I9: =H9+I8 -> 0 | J9: =I9+J8 -> 0 | K9: =J9+K8 -> 3 | ... V9: =U9+V8 -> 129
B10: Go-Live Zones This Quarter | C10: =IF(COLUMN(C8)-COLUMN($C$8)>=Assumptions!$C$48,INDEX($C$8:$V$8,1,COLUMN(C8)-COLUMN($C$8)+1-Assumptions!$C$48),0) -> 0 | D10: =IF(COLUMN(D8)-COLUMN($C$8)>=Assumptions!$C$48,INDEX($C$8:$V$8,1,COLUMN(D8)-COLUMN($C$8)+1-Assumptions!$C$48),0) -> 0 | E10: =IF(COLUMN(E8)-COLUMN($C$8)>=Assumptions!$C$48,INDEX($C$8:$V$8,1,COLUMN(E8)-COLUMN($C$8)+1-Assumptions!$C$48),0) -> 0 | F10: =IF(COLUMN(F8)-COLUMN($C$8)>=Assumptions!$C$48,INDEX($C$8:$V$8,1,COLUMN(F8)-COLUMN($C$8)+1-Assumptions!$C$48),0) -> 0 | G10: =IF(COLUMN(G8)-COLUMN($C$8)>=Assumptions!$C$48,INDEX($C$8:$V$8,1,COLUMN(G8)-COLUMN($C$8)+1-Assumptions!$C$48),0) -> 0 | H10: =IF(COLUMN(H8)-COLUMN($C$8)>=Assumptions!$C$48,INDEX($C$8:$V$8,1,COLUMN(H8)-COLUMN($C$8)+1-Assumptions!$C$48),0) -> 0 | I10: =IF(COLUMN(I8)-COLUMN($C$8)>=Assumptions!$C$48,INDEX($C$8:$V$8,1,COLUMN(I8)-COLUMN($C$8)+1-Assumptions!$C$48),0) -> 0 | J10: =IF(COLUMN(J8)-COLUMN($C$8)>=Assumptions!$C$48,INDEX($C$8:$V$8,1,COLUMN(J8)-COLUMN($C$8)+1-Assumptions!$C$48),0) -> 0 | ... V10: =IF(COLUMN(V8)-COLUMN($C$8)>=Assumptions!$C$48,INDEX($C$8:$V$8,1,COLUMN(V8)-COLUMN($C$8)+1-Assumptions!$C$48),0) -> 15
B11: Cumulative Go-Live Zones | C11: =C10 -> 0 | D11: =C11+D10 -> 0 | E11: =D11+E10 -> 0 | F11: =E11+F10 -> 0 | G11: =F11+G10 -> 0 | H11: =G11+H10 -> 0 | I11: =H11+I10 -> 0 | J11: =I11+J10 -> 0 | K11: =J11+K10 -> 0 | ... V11: =U11+V10 -> 84

Sheet Anchor Revenue
B1: Anchor Revenue
C3: Q1'27 | D3: Q2'27 | E3: Q3'27 | F3: Q4'27 | G3: Q1'28 | H3: Q2'28 | I3: Q3'28 | J3: Q4'28 | K3: Q1'29 | L3: Q2'29 | M3: Q3'29 | N3: Q4'29 | O3: Q1'30 | P3: Q2'30 | Q3: Q3'30 | R3: Q4'30 | S3: Q1'31 | T3: Q2'31 | U3: Q3'31 | V3: Q4'31
C4: 1 | D4: 2 | E4: 3 | F4: 4 | G4: 5 | H4: 6 | I4: 7 | J4: 8 | K4: 9 | L4: 10 | M4: 11 | N4: 12 | O4: 13 | P4: 14 | Q4: 15 | R4: 16 | S4: 17 | T4: 18 | U4: 19 | V4: 20
B6: Cumulative Zones Live (helper)
B7: Partner 1 Atlas | C7: =SUM(Assumptions!$C$30:C$30) -> 0 | D7: =SUM(Assumptions!$C$30:D$30) -> 0 | E7: =SUM(Assumptions!$C$30:E$30) -> 0 | F7: =SUM(Assumptions!$C$30:F$30) -> 3 | G7: =SUM(Assumptions!$C$30:G$30) -> 6 | H7: =SUM(Assumptions!$C$30:H$30) -> 6 | I7: =SUM(Assumptions!$C$30:I$30) -> 6 | J7: =SUM(Assumptions!$C$30:J$30) -> 6 | K7: =SUM(Assumptions!$C$30:J$30) -> 6 | L7: =SUM(Assumptions!$C$30:J$30) -> 6 | M7: =SUM(Assumptions!$C$30:J$30) -> 6 | N7: =SUM(Assumptions!$C$30:J$30) -> 6 | O7: =SUM(Assumptions!$C$30:J$30) -> 6 | P7: =SUM(Assumptions!$C$30:J$30) -> 6 | Q7: =SUM(Assumptions!$C$30:J$30) -> 6 | R7: =SUM(Assumptions!$C$30:J$30) -> 6 | S7: =SUM(Assumptions!$C$30:J$30) -> 6 | T7: =SUM(Assumptions!$C$30:J$30) -> 6 | U7: =SUM(Assumptions!$C$30:J$30) -> 6 | V7: =SUM(Assumptions!$C$30:J$30) -> 6
B8: Partner 2 Titan | C8: =SUM(Assumptions!$C$31:C$31) -> 0 | D8: =SUM(Assumptions!$C$31:D$31) -> 0 | E8: =SUM(Assumptions!$C$31:E$31) -> 0 | F8: =SUM(Assumptions!$C$31:F$31) -> 0 | G8: =SUM(Assumptions!$C$31:G$31) -> 2 | H8: =SUM(Assumptions!$C$31:H$31) -> 4 | I8: =SUM(Assumptions!$C$31:I$31) -> 4 | J8: =SUM(Assumptions!$C$31:J$31) -> 4 | K8: =SUM(Assumptions!$C$31:J$31) -> 4 | L8: =SUM(Assumptions!$C$31:J$31) -> 4 | M8: =SUM(Assumptions!$C$31:J$31) -> 4 | N8: =SUM(Assumptions!$C$31:J$31) -> 4 | O8: =SUM(Assumptions!$C$31:J$31) -> 4 | P8: =SUM(Assumptions!$C$31:J$31) -> 4 | Q8: =SUM(Assumptions!$C$31:J$31) -> 4 | R8: =SUM(Assumptions!$C$31:J$31) -> 4 | S8: =SUM(Assumptions!$C$31:J$31) -> 4 | T8: =SUM(Assumptions!$C$31:J$31) -> 4 | U8: =SUM(Assumptions!$C$31:J$31) -> 4 | V8: =SUM(Assumptions!$C$31:J$31) -> 4
B9: Partner 3 Apex | C9: =SUM(Assumptions!$C$32:C$32) -> 0 | D9: =SUM(Assumptions!$C$32:D$32) -> 0 | E9: =SUM(Assumptions!$C$32:E$32) -> 0 | F9: =SUM(Assumptions!$C$32:F$32) -> 0 | G9: =SUM(Assumptions!$C$32:G$32) -> 0 | H9: =SUM(Assumptions!$C$32:H$32) -> 2 | I9: =SUM(Assumptions!$C$32:I$32) -> 5 | J9: =SUM(Assumptions!$C$32:J$32) -> 5 | K9: =SUM(Assumptions!$C$32:J$32) -> 5 | L9: =SUM(Assumptions!$C$32:J$32) -> 5 | M9: =SUM(Assumptions!$C$32:J$32) -> 5 | N9: =SUM(Assumptions!$C$32:J$32) -> 5 | O9: =SUM(Assumptions!$C$32:J$32) -> 5 | P9: =SUM(Assumptions!$C$32:J$32) -> 5 | Q9: =SUM(Assumptions!$C$32:J$32) -> 5 | R9: =SUM(Assumptions!$C$32:J$32) -> 5 | S9: =SUM(Assumptions!$C$32:J$32) -> 5 | T9: =SUM(Assumptions!$C$32:J$32) -> 5 | U9: =SUM(Assumptions!$C$32:J$32) -> 5 | V9: =SUM(Assumptions!$C$32:J$32) -> 5
B10: Partner 4 Vanguard | C10: =SUM(Assumptions!$C$33:C$33) -> 0 | D10: =SUM(Assumptions!$C$33:D$33) -> 0 | E10: =SUM(Assumptions!$C$33:E$33) -> 0 | F10: =SUM(Assumptions!$C$33:F$33) -> 0 | G10: =SUM(Assumptions!$C$33:G$33) -> 0 | H10: =SUM(Assumptions!$C$33:H$33) -> 0 | I10: =SUM(Assumptions!$C$33:I$33) -> 2 | J10: =SUM(Assumptions!$C$33:J$33) -> 3 | K10: =SUM(Assumptions!$C$33:J$33) -> 3 | L10: =SUM(Assumptions!$C$33:J$33) -> 3 | M10: =SUM(Assumptions!$C$33:J$33) -> 3 | N10: =SUM(Assumptions!$C$33:J$33) -> 3 | O10: =SUM(Assumptions!$C$33:J$33) -> 3 | P10: =SUM(Assumptions!$C$33:J$33) -> 3 | Q10: =SUM(Assumptions!$C$33:J$33) -> 3 | R10: =SUM(Assumptions!$C$33:J$33) -> 3 | S10: =SUM(Assumptions!$C$33:J$33) -> 3 | T10: =SUM(Assumptions!$C$33:J$33) -> 3 | U10: =SUM(Assumptions!$C$33:J$33) -> 3 | V10: =SUM(Assumptions!$C$33:J$33) -> 3
B11: Partner 5 Nimble | C11: =SUM(Assumptions!$C$34:C$34) -> 0 | D11: =SUM(Assumptions!$C$34:D$34) -> 0 | E11: =SUM(Assumptions!$C$34:E$34) -> 0 | F11: =SUM(Assumptions!$C$34:F$34) -> 0 | G11: =SUM(Assumptions!$C$34:G$34) -> 0 | H11: =SUM(Assumptions!$C$34:H$34) -> 0 | I11: =SUM(Assumptions!$C$34:I$34) -> 0 | J11: =SUM(Assumptions!$C$34:J$34) -> 2 | K11: =SUM(Assumptions!$C$34:J$34) -> 2 | L11: =SUM(Assumptions!$C$34:J$34) -> 2 | M11: =SUM(Assumptions!$C$34:J$34) -> 2 | N11: =SUM(Assumptions!$C$34:J$34) -> 2 | O11: =SUM(Assumptions!$C$34:J$34) -> 2 | P11: =SUM(Assumptions!$C$34:J$34) -> 2 | Q11: =SUM(Assumptions!$C$34:J$34) -> 2 | R11: =SUM(Assumptions!$C$34:J$34) -> 2 | S11: =SUM(Assumptions!$C$34:J$34) -> 2 | T11: =SUM(Assumptions!$C$34:J$34) -> 2 | U11: =SUM(Assumptions!$C$34:J$34) -> 2 | V11: =SUM(Assumptions!$C$34:J$34) -> 2
B13: Implementation Revenue
B14: Partner 1 Atlas | C14: =IF(1=Assumptions!$C$39,Assumptions!$C$14*Assumptions!$C$24,0)+IF(1=Assumptions!$C$40,Assumptions!$C$14*Assumptions!$C$25,0)+IF(1=Assumptions!$C$40+4,Assumptions!$C$14*Assumptions!$C$26,0) -> 0 | D14: =IF(2=Assumptions!$C$39,Assumptions!$C$14*Assumptions!$C$24,0)+IF(2=Assumptions!$C$40,Assumptions!$C$14*Assumptions!$C$25,0)+IF(2=Assumptions!$C$40+4,Assumptions!$C$14*Assumptions!$C$26,0) -> 840000 | E14: =IF(3=Assumptions!$C$39,Assumptions!$C$14*Assumptions!$C$24,0)+IF(3=Assumptions!$C$40,Assumptions!$C$14*Assumptions!$C$25,0)+IF(3=Assumptions!$C$40+4,Assumptions!$C$14*Assumptions!$C$26,0) -> 0 | F14: =IF(4=Assumptions!$C$39,Assumptions!$C$14*Assumptions!$C$24,0)+IF(4=Assumptions!$C$40,Assumptions!$C$14*Assumptions!$C$25,0)+IF(4=Assumptions!$C$40+4,Assumptions!$C$14*Assumptions!$C$26,0) -> 735000 | G14: =IF(5=Assumptions!$C$39,Assumptions!$C$14*Assumptions!$C$24,0)+IF(5=Assumptions!$C$40,Assumptions!$C$14*Assumptions!$C$25,0)+IF(5=Assumptions!$C$40+4,Assumptions!$C$14*Assumptions!$C$26,0) -> 0 | H14: =IF(6=Assumptions!$C$39,Assumptions!$C$14*Assumptions!$C$24,0)+IF(6=Assumptions!$C$40,Assumptions!$C$14*Assumptions!$C$25,0)+IF(6=Assumptions!$C$40+4,Assumptions!$C$14*Assumptions!$C$26,0) -> 0 | I14: =IF(7=Assumptions!$C$39,Assumptions!$C$14*Assumptions!$C$24,0)+IF(7=Assumptions!$C$40,Assumptions!$C$14*Assumptions!$C$25,0)+IF(7=Assumptions!$C$40+4,Assumptions!$C$14*Assumptions!$C$26,0) -> 0 | J14: =IF(8=Assumptions!$C$39,Assumptions!$C$14*Assumptions!$C$24,0)+IF(8=Assumptions!$C$40,Assumptions!$C$14*Assumptions!$C$25,0)+IF(8=Assumptions!$C$40+4,Assumptions!$C$14*Assumptions!$C$26,0) -> 525000 | K14: =IF(9=Assumptions!$C$39,Assumptions!$C$14*Assumptions!$C$24,0)+IF(9=Assumptions!$C$40,Assumptions!$C$14*Assumptions!$C$25,0)+IF(9=Assumptions!$C$40+4,Assumptions!$C$14*Assumptions!$C$26,0) -> 0 | L14: =IF(10=Assumptions!$C$39,Assumptions!$C$14*Assumptions!$C$24,0)+IF(10=Assumptions!$C$40,Assumptions!$C$14*Assumptions!$C$25,0)+IF(10=Assumptions!$C$40+4,Assumptions!$C$14*Assumptions!$C$26,0) -> 0 | M14: =IF(11=Assumptions!$C$39,Assumptions!$C$14*Assumptions!$C$24,0)+IF(11=Assumptions!$C$40,Assumptions!$C$14*Assumptions!$C$25,0)+IF(11=Assumptions!$C$40+4,Assumptions!$C$14*Assumptions!$C$26,0) -> 0 | N14: =IF(12=Assumptions!$C$39,Assumptions!$C$14*Assumptions!$C$24,0)+IF(12=Assumptions!$C$40,Assumptions!$C$14*Assumptions!$C$25,0)+IF(12=Assumptions!$C$40+4,Assumptions!$C$14*Assumptions!$C$26,0) -> 0 | O14: =IF(13=Assumptions!$C$39,Assumptions!$C$14*Assumptions!$C$24,0)+IF(13=Assumptions!$C$40,Assumptions!$C$14*Assumptions!$C$25,0)+IF(13=Assumptions!$C$40+4,Assumptions!$C$14*Assumptions!$C$26,0) -> 0 | P14: =IF(14=Assumptions!$C$39,Assumptions!$C$14*Assumptions!$C$24,0)+IF(14=Assumptions!$C$40,Assumptions!$C$14*Assumptions!$C$25,0)+IF(14=Assumptions!$C$40+4,Assumptions!$C$14*Assumptions!$C$26,0) -> 0 | Q14: =IF(15=Assumptions!$C$39,Assumptions!$C$14*Assumptions!$C$24,0)+IF(15=Assumptions!$C$40,Assumptions!$C$14*Assumptions!$C$25,0)+IF(15=Assumptions!$C$40+4,Assumptions!$C$14*Assumptions!$C$26,0) -> 0 | R14: =IF(16=Assumptions!$C$39,Assumptions!$C$14*Assumptions!$C$24,0)+IF(16=Assumptions!$C$40,Assumptions!$C$14*Assumptions!$C$25,0)+IF(16=Assumptions!$C$40+4,Assumptions!$C$14*Assumptions!$C$26,0) -> 0 | S14: =IF(17=Assumptions!$C$39,Assumptions!$C$14*Assumptions!$C$24,0)+IF(17=Assumptions!$C$40,Assumptions!$C$14*Assumptions!$C$25,0)+IF(17=Assumptions!$C$40+4,Assumptions!$C$14*Assumptions!$C$26,0) -> 0 | T14: =IF(18=Assumptions!$C$39,Assumptions!$C$14*Assumptions!$C$24,0)+IF(18=Assumptions!$C$40,Assumptions!$C$14*Assumptions!$C$25,0)+IF(18=Assumptions!$C$40+4,Assumptions!$C$14*Assumptions!$C$26,0) -> 0 | U14: =IF(19=Assumptions!$C$39,Assumptions!$C$14*Assumptions!$C$24,0)+IF(19=Assumptions!$C$40,Assumptions!$C$14*Assumptions!$C$25,0)+IF(19=Assumptions!$C$40+4,Assumptions!$C$14*Assumptions!$C$26,0) -> 0 | V14: =IF(20=Assumptions!$C$39,Assumptions!$C$14*Assumptions!$C$24,0)+IF(20=Assumptions!$C$40,Assumptions!$C$14*Assumptions!$C$25,0)+IF(20=Assumptions!$C$40+4,Assumptions!$C$14*Assumptions!$C$26,0) -> 0
B16: Partner 2 Titan | C16: =IF(1=Assumptions!$D$39,Assumptions!$D$14*Assumptions!$C$24,0)+IF(1=Assumptions!$D$40,Assumptions!$D$14*Assumptions!$C$25,0)+IF(1=Assumptions!$D$40+4,Assumptions!$D$14*Assumptions!$C$26,0) -> 0 | D16: =IF(2=Assumptions!$D$39,Assumptions!$D$14*Assumptions!$C$24,0)+IF(2=Assumptions!$D$40,Assumptions!$D$14*Assumptions!$C$25,0)+IF(2=Assumptions!$D$40+4,Assumptions!$D$14*Assumptions!$C$26,0) -> 0 | E16: =IF(3=Assumptions!$D$39,Assumptions!$D$14*Assumptions!$C$24,0)+IF(3=Assumptions!$D$40,Assumptions!$D$14*Assumptions!$C$25,0)+IF(3=Assumptions!$D$40+4,Assumptions!$D$14*Assumptions!$C$26,0) -> 560000 | F16: =IF(4=Assumptions!$D$39,Assumptions!$D$14*Assumptions!$C$24,0)+IF(4=Assumptions!$D$40,Assumptions!$D$14*Assumptions!$C$25,0)+IF(4=Assumptions!$D$40+4,Assumptions!$D$14*Assumptions!$C$26,0) -> 0 | G16: =IF(5=Assumptions!$D$39,Assumptions!$D$14*Assumptions!$C$24,0)+IF(5=Assumptions!$D$40,Assumptions!$D$14*Assumptions!$C$25,0)+IF(5=Assumptions!$D$40+4,Assumptions!$D$14*Assumptions!$C$26,0) -> 490000 | H16: =IF(6=Assumptions!$D$39,Assumptions!$D$14*Assumptions!$C$24,0)+IF(6=Assumptions!$D$40,Assumptions!$D$14*Assumptions!$C$25,0)+IF(6=Assumptions!$D$40+4,Assumptions!$D$14*Assumptions!$C$26,0) -> 0 | I16: =IF(7=Assumptions!$D$39,Assumptions!$D$14*Assumptions!$C$24,0)+IF(7=Assumptions!$D$40,Assumptions!$D$14*Assumptions!$C$25,0)+IF(7=Assumptions!$D$40+4,Assumptions!$D$14*Assumptions!$C$26,0) -> 0 | J16: =IF(8=Assumptions!$D$39,Assumptions!$D$14*Assumptions!$C$24,0)+IF(8=Assumptions!$D$40,Assumptions!$D$14*Assumptions!$C$25,0)+IF(8=Assumptions!$D$40+4,Assumptions!$D$14*Assumptions!$C$26,0) -> 0 | K16: =IF(9=Assumptions!$D$39,Assumptions!$D$14*Assumptions!$C$24,0)+IF(9=Assumptions!$D$40,Assumptions!$D$14*Assumptions!$C$25,0)+IF(9=Assumptions!$D$40+4,Assumptions!$D$14*Assumptions!$C$26,0) -> 350000 | L16: =IF(10=Assumptions!$D$39,Assumptions!$D$14*Assumptions!$C$24,0)+IF(10=Assumptions!$D$40,Assumptions!$D$14*Assumptions!$C$25,0)+IF(10=Assumptions!$D$40+4,Assumptions!$D$14*Assumptions!$C$26,0) -> 0 | M16: =IF(11=Assumptions!$D$39,Assumptions!$D$14*Assumptions!$C$24,0)+IF(11=Assumptions!$D$40,Assumptions!$D$14*Assumptions!$C$25,0)+IF(11=Assumptions!$D$40+4,Assumptions!$D$14*Assumptions!$C$26,0) -> 0 | N16: =IF(12=Assumptions!$D$39,Assumptions!$D$14*Assumptions!$C$24,0)+IF(12=Assumptions!$D$40,Assumptions!$D$14*Assumptions!$C$25,0)+IF(12=Assumptions!$D$40+4,Assumptions!$D$14*Assumptions!$C$26,0) -> 0 | O16: =IF(13=Assumptions!$D$39,Assumptions!$D$14*Assumptions!$C$24,0)+IF(13=Assumptions!$D$40,Assumptions!$D$14*Assumptions!$C$25,0)+IF(13=Assumptions!$D$40+4,Assumptions!$D$14*Assumptions!$C$26,0) -> 0 | P16: =IF(14=Assumptions!$D$39,Assumptions!$D$14*Assumptions!$C$24,0)+IF(14=Assumptions!$D$40,Assumptions!$D$14*Assumptions!$C$25,0)+IF(14=Assumptions!$D$40+4,Assumptions!$D$14*Assumptions!$C$26,0) -> 0 | Q16: =IF(15=Assumptions!$D$39,Assumptions!$D$14*Assumptions!$C$24,0)+IF(15=Assumptions!$D$40,Assumptions!$D$14*Assumptions!$C$25,0)+IF(15=Assumptions!$D$40+4,Assumptions!$D$14*Assumptions!$C$26,0) -> 0 | R16: =IF(16=Assumptions!$D$39,Assumptions!$D$14*Assumptions!$C$24,0)+IF(16=Assumptions!$D$40,Assumptions!$D$14*Assumptions!$C$25,0)+IF(16=Assumptions!$D$40+4,Assumptions!$D$14*Assumptions!$C$26,0) -> 0 | S16: =IF(17=Assumptions!$D$39,Assumptions!$D$14*Assumptions!$C$24,0)+IF(17=Assumptions!$D$40,Assumptions!$D$14*Assumptions!$C$25,0)+IF(17=Assumptions!$D$40+4,Assumptions!$D$14*Assumptions!$C$26,0) -> 0 | T16: =IF(18=Assumptions!$D$39,Assumptions!$D$14*Assumptions!$C$24,0)+IF(18=Assumptions!$D$40,Assumptions!$D$14*Assumptions!$C$25,0)+IF(18=Assumptions!$D$40+4,Assumptions!$D$14*Assumptions!$C$26,0) -> 0 | U16: =IF(19=Assumptions!$D$39,Assumptions!$D$14*Assumptions!$C$24,0)+IF(19=Assumptions!$D$40,Assumptions!$D$14*Assumptions!$C$25,0)+IF(19=Assumptions!$D$40+4,Assumptions!$D$14*Assumptions!$C$26,0) -> 0 | V16: =IF(20=Assumptions!$D$39,Assumptions!$D$14*Assumptions!$C$24,0)+IF(20=Assumptions!$D$40,Assumptions!$D$14*Assumptions!$C$25,0)+IF(20=Assumptions!$D$40+4,Assumptions!$D$14*Assumptions!$C$26,0) -> 0
B18: Partner 3 Apex | C18: =IF(1=Assumptions!$E$39,Assumptions!$E$14*Assumptions!$C$24,0)+IF(1=Assumptions!$E$40,Assumptions!$E$14*Assumptions!$C$25,0)+IF(1=Assumptions!$E$40+4,Assumptions!$E$14*Assumptions!$C$26,0) -> 0 | D18: =IF(2=Assumptions!$E$39,Assumptions!$E$14*Assumptions!$C$24,0)+IF(2=Assumptions!$E$40,Assumptions!$E$14*Assumptions!$C$25,0)+IF(2=Assumptions!$E$40+4,Assumptions!$E$14*Assumptions!$C$26,0) -> 0 | E18: =IF(3=Assumptions!$E$39,Assumptions!$E$14*Assumptions!$C$24,0)+IF(3=Assumptions!$E$40,Assumptions!$E$14*Assumptions!$C$25,0)+IF(3=Assumptions!$E$40+4,Assumptions!$E$14*Assumptions!$C$26,0) -> 0 | F18: =IF(4=Assumptions!$E$39,Assumptions!$E$14*Assumptions!$C$24,0)+IF(4=Assumptions!$E$40,Assumptions!$E$14*Assumptions!$C$25,0)+IF(4=Assumptions!$E$40+4,Assumptions!$E$14*Assumptions!$C$26,0) -> 700000 | G18: =IF(5=Assumptions!$E$39,Assumptions!$E$14*Assumptions!$C$24,0)+IF(5=Assumptions!$E$40,Assumptions!$E$14*Assumptions!$C$25,0)+IF(5=Assumptions!$E$40+4,Assumptions!$E$14*Assumptions!$C$26,0) -> 0 | H18: =IF(6=Assumptions!$E$39,Assumptions!$E$14*Assumptions!$C$24,0)+IF(6=Assumptions!$E$40,Assumptions!$E$14*Assumptions!$C$25,0)+IF(6=Assumptions!$E$40+4,Assumptions!$E$14*Assumptions!$C$26,0) -> 612500 | I18: =IF(7=Assumptions!$E$39,Assumptions!$E$14*Assumptions!$C$24,0)+IF(7=Assumptions!$E$40,Assumptions!$E$14*Assumptions!$C$25,0)+IF(7=Assumptions!$E$40+4,Assumptions!$E$14*Assumptions!$C$26,0) -> 0 | J18: =IF(8=Assumptions!$E$39,Assumptions!$E$14*Assumptions!$C$24,0)+IF(8=Assumptions!$E$40,Assumptions!$E$14*Assumptions!$C$25,0)+IF(8=Assumptions!$E$40+4,Assumptions!$E$14*Assumptions!$C$26,0) -> 0 | K18: =IF(9=Assumptions!$E$39,Assumptions!$E$14*Assumptions!$C$24,0)+IF(9=Assumptions!$E$40,Assumptions!$E$14*Assumptions!$C$25,0)+IF(9=Assumptions!$E$40+4,Assumptions!$E$14*Assumptions!$C$26,0) -> 0 | L18: =IF(10=Assumptions!$E$39,Assumptions!$E$14*Assumptions!$C$24,0)+IF(10=Assumptions!$E$40,Assumptions!$E$14*Assumptions!$C$25,0)+IF(10=Assumptions!$E$40+4,Assumptions!$E$14*Assumptions!$C$26,0) -> 437500 | M18: =IF(11=Assumptions!$E$39,Assumptions!$E$14*Assumptions!$C$24,0)+IF(11=Assumptions!$E$40,Assumptions!$E$14*Assumptions!$C$25,0)+IF(11=Assumptions!$E$40+4,Assumptions!$E$14*Assumptions!$C$26,0) -> 0 | N18: =IF(12=Assumptions!$E$39,Assumptions!$E$14*Assumptions!$C$24,0)+IF(12=Assumptions!$E$40,Assumptions!$E$14*Assumptions!$C$25,0)+IF(12=Assumptions!$E$40+4,Assumptions!$E$14*Assumptions!$C$26,0) -> 0 | O18: =IF(13=Assumptions!$E$39,Assumptions!$E$14*Assumptions!$C$24,0)+IF(13=Assumptions!$E$40,Assumptions!$E$14*Assumptions!$C$25,0)+IF(13=Assumptions!$E$40+4,Assumptions!$E$14*Assumptions!$C$26,0) -> 0 | P18: =IF(14=Assumptions!$E$39,Assumptions!$E$14*Assumptions!$C$24,0)+IF(14=Assumptions!$E$40,Assumptions!$E$14*Assumptions!$C$25,0)+IF(14=Assumptions!$E$40+4,Assumptions!$E$14*Assumptions!$C$26,0) -> 0 | Q18: =IF(15=Assumptions!$E$39,Assumptions!$E$14*Assumptions!$C$24,0)+IF(15=Assumptions!$E$40,Assumptions!$E$14*Assumptions!$C$25,0)+IF(15=Assumptions!$E$40+4,Assumptions!$E$14*Assumptions!$C$26,0) -> 0 | R18: =IF(16=Assumptions!$E$39,Assumptions!$E$14*Assumptions!$C$24,0)+IF(16=Assumptions!$E$40,Assumptions!$E$14*Assumptions!$C$25,0)+IF(16=Assumptions!$E$40+4,Assumptions!$E$14*Assumptions!$C$26,0) -> 0 | S18: =IF(17=Assumptions!$E$39,Assumptions!$E$14*Assumptions!$C$24,0)+IF(17=Assumptions!$E$40,Assumptions!$E$14*Assumptions!$C$25,0)+IF(17=Assumptions!$E$40+4,Assumptions!$E$14*Assumptions!$C$26,0) -> 0 | T18: =IF(18=Assumptions!$E$39,Assumptions!$E$14*Assumptions!$C$24,0)+IF(18=Assumptions!$E$40,Assumptions!$E$14*Assumptions!$C$25,0)+IF(18=Assumptions!$E$40+4,Assumptions!$E$14*Assumptions!$C$26,0) -> 0 | U18: =IF(19=Assumptions!$E$39,Assumptions!$E$14*Assumptions!$C$24,0)+IF(19=Assumptions!$E$40,Assumptions!$E$14*Assumptions!$C$25,0)+IF(19=Assumptions!$E$40+4,Assumptions!$E$14*Assumptions!$C$26,0) -> 0 | V18: =IF(20=Assumptions!$E$39,Assumptions!$E$14*Assumptions!$C$24,0)+IF(20=Assumptions!$E$40,Assumptions!$E$14*Assumptions!$C$25,0)+IF(20=Assumptions!$E$40+4,Assumptions!$E$14*Assumptions!$C$26,0) -> 0
B20: Partner 4 Vanguard | C20: =IF(1=Assumptions!$F$39,Assumptions!$F$14*Assumptions!$C$24,0)+IF(1=Assumptions!$F$40,Assumptions!$F$14*Assumptions!$C$25,0)+IF(1=Assumptions!$F$40+4,Assumptions!$F$14*Assumptions!$C$26,0) -> 0 | D20: =IF(2=Assumptions!$F$39,Assumptions!$F$14*Assumptions!$C$24,0)+IF(2=Assumptions!$F$40,Assumptions!$F$14*Assumptions!$C$25,0)+IF(2=Assumptions!$F$40+4,Assumptions!$F$14*Assumptions!$C$26,0) -> 0 | E20: =IF(3=Assumptions!$F$39,Assumptions!$F$14*Assumptions!$C$24,0)+IF(3=Assumptions!$F$40,Assumptions!$F$14*Assumptions!$C$25,0)+IF(3=Assumptions!$F$40+4,Assumptions!$F$14*Assumptions!$C$26,0) -> 0 | F20: =IF(4=Assumptions!$F$39,Assumptions!$F$14*Assumptions!$C$24,0)+IF(4=Assumptions!$F$40,Assumptions!$F$14*Assumptions!$C$25,0)+IF(4=Assumptions!$F$40+4,Assumptions!$F$14*Assumptions!$C$26,0) -> 0 | G20: =IF(5=Assumptions!$F$39,Assumptions!$F$14*Assumptions!$C$24,0)+IF(5=Assumptions!$F$40,Assumptions!$F$14*Assumptions!$C$25,0)+IF(5=Assumptions!$F$40+4,Assumptions!$F$14*Assumptions!$C$26,0) -> 420000 | H20: =IF(6=Assumptions!$F$39,Assumptions!$F$14*Assumptions!$C$24,0)+IF(6=Assumptions!$F$40,Assumptions!$F$14*Assumptions!$C$25,0)+IF(6=Assumptions!$F$40+4,Assumptions!$F$14*Assumptions!$C$26,0) -> 0 | I20: =IF(7=Assumptions!$F$39,Assumptions!$F$14*Assumptions!$C$24,0)+IF(7=Assumptions!$F$40,Assumptions!$F$14*Assumptions!$C$25,0)+IF(7=Assumptions!$F$40+4,Assumptions!$F$14*Assumptions!$C$26,0) -> 367500 | J20: =IF(8=Assumptions!$F$39,Assumptions!$F$14*Assumptions!$C$24,0)+IF(8=Assumptions!$F$40,Assumptions!$F$14*Assumptions!$C$25,0)+IF(8=Assumptions!$F$40+4,Assumptions!$F$14*Assumptions!$C$26,0) -> 0 | K20: =IF(9=Assumptions!$F$39,Assumptions!$F$14*Assumptions!$C$24,0)+IF(9=Assumptions!$F$40,Assumptions!$F$14*Assumptions!$C$25,0)+IF(9=Assumptions!$F$40+4,Assumptions!$F$14*Assumptions!$C$26,0) -> 0 | L20: =IF(10=Assumptions!$F$39,Assumptions!$F$14*Assumptions!$C$24,0)+IF(10=Assumptions!$F$40,Assumptions!$F$14*Assumptions!$C$25,0)+IF(10=Assumptions!$F$40+4,Assumptions!$F$14*Assumptions!$C$26,0) -> 0 | M20: =IF(11=Assumptions!$F$39,Assumptions!$F$14*Assumptions!$C$24,0)+IF(11=Assumptions!$F$40,Assumptions!$F$14*Assumptions!$C$25,0)+IF(11=Assumptions!$F$40+4,Assumptions!$F$14*Assumptions!$C$26,0) -> 262500 | N20: =IF(12=Assumptions!$F$39,Assumptions!$F$14*Assumptions!$C$24,0)+IF(12=Assumptions!$F$40,Assumptions!$F$14*Assumptions!$C$25,0)+IF(12=Assumptions!$F$40+4,Assumptions!$F$14*Assumptions!$C$26,0) -> 0 | O20: =IF(13=Assumptions!$F$39,Assumptions!$F$14*Assumptions!$C$24,0)+IF(13=Assumptions!$F$40,Assumptions!$F$14*Assumptions!$C$25,0)+IF(13=Assumptions!$F$40+4,Assumptions!$F$14*Assumptions!$C$26,0) -> 0 | P20: =IF(14=Assumptions!$F$39,Assumptions!$F$14*Assumptions!$C$24,0)+IF(14=Assumptions!$F$40,Assumptions!$F$14*Assumptions!$C$25,0)+IF(14=Assumptions!$F$40+4,Assumptions!$F$14*Assumptions!$C$26,0) -> 0 | Q20: =IF(15=Assumptions!$F$39,Assumptions!$F$14*Assumptions!$C$24,0)+IF(15=Assumptions!$F$40,Assumptions!$F$14*Assumptions!$C$25,0)+IF(15=Assumptions!$F$40+4,Assumptions!$F$14*Assumptions!$C$26,0) -> 0 | R20: =IF(16=Assumptions!$F$39,Assumptions!$F$14*Assumptions!$C$24,0)+IF(16=Assumptions!$F$40,Assumptions!$F$14*Assumptions!$C$25,0)+IF(16=Assumptions!$F$40+4,Assumptions!$F$14*Assumptions!$C$26,0) -> 0 | S20: =IF(17=Assumptions!$F$39,Assumptions!$F$14*Assumptions!$C$24,0)+IF(17=Assumptions!$F$40,Assumptions!$F$14*Assumptions!$C$25,0)+IF(17=Assumptions!$F$40+4,Assumptions!$F$14*Assumptions!$C$26,0) -> 0 | T20: =IF(18=Assumptions!$F$39,Assumptions!$F$14*Assumptions!$C$24,0)+IF(18=Assumptions!$F$40,Assumptions!$F$14*Assumptions!$C$25,0)+IF(18=Assumptions!$F$40+4,Assumptions!$F$14*Assumptions!$C$26,0) -> 0 | U20: =IF(19=Assumptions!$F$39,Assumptions!$F$14*Assumptions!$C$24,0)+IF(19=Assumptions!$F$40,Assumptions!$F$14*Assumptions!$C$25,0)+IF(19=Assumptions!$F$40+4,Assumptions!$F$14*Assumptions!$C$26,0) -> 0 | V20: =IF(20=Assumptions!$F$39,Assumptions!$F$14*Assumptions!$C$24,0)+IF(20=Assumptions!$F$40,Assumptions!$F$14*Assumptions!$C$25,0)+IF(20=Assumptions!$F$40+4,Assumptions!$F$14*Assumptions!$C$26,0) -> 0
B22: Partner 5 Nimble | C22: =IF(1=Assumptions!$G$39,Assumptions!$G$14*Assumptions!$C$24,0)+IF(1=Assumptions!$G$40,Assumptions!$G$14*Assumptions!$C$25,0)+IF(1=Assumptions!$G$40+4,Assumptions!$G$14*Assumptions!$C$26,0) -> 0 | D22: =IF(2=Assumptions!$G$39,Assumptions!$G$14*Assumptions!$C$24,0)+IF(2=Assumptions!$G$40,Assumptions!$G$14*Assumptions!$C$25,0)+IF(2=Assumptions!$G$40+4,Assumptions!$G$14*Assumptions!$C$26,0) -> 0 | E22: =IF(3=Assumptions!$G$39,Assumptions!$G$14*Assumptions!$C$24,0)+IF(3=Assumptions!$G$40,Assumptions!$G$14*Assumptions!$C$25,0)+IF(3=Assumptions!$G$40+4,Assumptions!$G$14*Assumptions!$C$26,0) -> 0 | F22: =IF(4=Assumptions!$G$39,Assumptions!$G$14*Assumptions!$C$24,0)+IF(4=Assumptions!$G$40,Assumptions!$G$14*Assumptions!$C$25,0)+IF(4=Assumptions!$G$40+4,Assumptions!$G$14*Assumptions!$C$26,0) -> 0 | G22: =IF(5=Assumptions!$G$39,Assumptions!$G$14*Assumptions!$C$24,0)+IF(5=Assumptions!$G$40,Assumptions!$G$14*Assumptions!$C$25,0)+IF(5=Assumptions!$G$40+4,Assumptions!$G$14*Assumptions!$C$26,0) -> 0 | H22: =IF(6=Assumptions!$G$39,Assumptions!$G$14*Assumptions!$C$24,0)+IF(6=Assumptions!$G$40,Assumptions!$G$14*Assumptions!$C$25,0)+IF(6=Assumptions!$G$40+4,Assumptions!$G$14*Assumptions!$C$26,0) -> 280000 | I22: =IF(7=Assumptions!$G$39,Assumptions!$G$14*Assumptions!$C$24,0)+IF(7=Assumptions!$G$40,Assumptions!$G$14*Assumptions!$C$25,0)+IF(7=Assumptions!$G$40+4,Assumptions!$G$14*Assumptions!$C$26,0) -> 0 | J22: =IF(8=Assumptions!$G$39,Assumptions!$G$14*Assumptions!$C$24,0)+IF(8=Assumptions!$G$40,Assumptions!$G$14*Assumptions!$C$25,0)+IF(8=Assumptions!$G$40+4,Assumptions!$G$14*Assumptions!$C$26,0) -> 245000 | K22: =IF(9=Assumptions!$G$39,Assumptions!$G$14*Assumptions!$C$24,0)+IF(9=Assumptions!$G$40,Assumptions!$G$14*Assumptions!$C$25,0)+IF(9=Assumptions!$G$40+4,Assumptions!$G$14*Assumptions!$C$26,0) -> 0 | L22: =IF(10=Assumptions!$G$39,Assumptions!$G$14*Assumptions!$C$24,0)+IF(10=Assumptions!$G$40,Assumptions!$G$14*Assumptions!$C$25,0)+IF(10=Assumptions!$G$40+4,Assumptions!$G$14*Assumptions!$C$26,0) -> 0 | M22: =IF(11=Assumptions!$G$39,Assumptions!$G$14*Assumptions!$C$24,0)+IF(11=Assumptions!$G$40,Assumptions!$G$14*Assumptions!$C$25,0)+IF(11=Assumptions!$G$40+4,Assumptions!$G$14*Assumptions!$C$26,0) -> 0 | N22: =IF(12=Assumptions!$G$39,Assumptions!$G$14*Assumptions!$C$24,0)+IF(12=Assumptions!$G$40,Assumptions!$G$14*Assumptions!$C$25,0)+IF(12=Assumptions!$G$40+4,Assumptions!$G$14*Assumptions!$C$26,0) -> 175000 | O22: =IF(13=Assumptions!$G$39,Assumptions!$G$14*Assumptions!$C$24,0)+IF(13=Assumptions!$G$40,Assumptions!$G$14*Assumptions!$C$25,0)+IF(13=Assumptions!$G$40+4,Assumptions!$G$14*Assumptions!$C$26,0) -> 0 | P22: =IF(14=Assumptions!$G$39,Assumptions!$G$14*Assumptions!$C$24,0)+IF(14=Assumptions!$G$40,Assumptions!$G$14*Assumptions!$C$25,0)+IF(14=Assumptions!$G$40+4,Assumptions!$G$14*Assumptions!$C$26,0) -> 0 | Q22: =IF(15=Assumptions!$G$39,Assumptions!$G$14*Assumptions!$C$24,0)+IF(15=Assumptions!$G$40,Assumptions!$G$14*Assumptions!$C$25,0)+IF(15=Assumptions!$G$40+4,Assumptions!$G$14*Assumptions!$C$26,0) -> 0 | R22: =IF(16=Assumptions!$G$39,Assumptions!$G$14*Assumptions!$C$24,0)+IF(16=Assumptions!$G$40,Assumptions!$G$14*Assumptions!$C$25,0)+IF(16=Assumptions!$G$40+4,Assumptions!$G$14*Assumptions!$C$26,0) -> 0 | S22: =IF(17=Assumptions!$G$39,Assumptions!$G$14*Assumptions!$C$24,0)+IF(17=Assumptions!$G$40,Assumptions!$G$14*Assumptions!$C$25,0)+IF(17=Assumptions!$G$40+4,Assumptions!$G$14*Assumptions!$C$26,0) -> 0 | T22: =IF(18=Assumptions!$G$39,Assumptions!$G$14*Assumptions!$C$24,0)+IF(18=Assumptions!$G$40,Assumptions!$G$14*Assumptions!$C$25,0)+IF(18=Assumptions!$G$40+4,Assumptions!$G$14*Assumptions!$C$26,0) -> 0 | U22: =IF(19=Assumptions!$G$39,Assumptions!$G$14*Assumptions!$C$24,0)+IF(19=Assumptions!$G$40,Assumptions!$G$14*Assumptions!$C$25,0)+IF(19=Assumptions!$G$40+4,Assumptions!$G$14*Assumptions!$C$26,0) -> 0 | V22: =IF(20=Assumptions!$G$39,Assumptions!$G$14*Assumptions!$C$24,0)+IF(20=Assumptions!$G$40,Assumptions!$G$14*Assumptions!$C$25,0)+IF(20=Assumptions!$G$40+4,Assumptions!$G$14*Assumptions!$C$26,0) -> 0
B24: Total Implementation | C24: =C14+C16+C18+C20+C22 -> 0 | D24: =D14+D16+D18+D20+D22 -> 840000 | E24: =E14+E16+E18+E20+E22 -> 560000 | F24: =F14+F16+F18+F20+F22 -> 1435000 | G24: =G14+G16+G18+G20+G22 -> 910000 | H24: =H14+H16+H18+H20+H22 -> 892500 | I24: =I14+I16+I18+I20+I22 -> 367500 | J24: =J14+J16+J18+J20+J22 -> 770000 | ... V24: =V14+V16+V18+V20+V22 -> 0
B26: NON-GAAP IMPL + CONSULTING FEE
B27: Partner 1 Atlas | C27: =IF(1=Assumptions!$C$39,Assumptions!$C$10*Assumptions!$C$44+Assumptions!$C$45,0) -> 0 | D27: =IF(2=Assumptions!$C$39,Assumptions!$C$10*Assumptions!$C$44+Assumptions!$C$45,0) -> 255000 | E27: =IF(3=Assumptions!$C$39,Assumptions!$C$10*Assumptions!$C$44+Assumptions!$C$45,0) -> 0 | F27: =IF(4=Assumptions!$C$39,Assumptions!$C$10*Assumptions!$C$44+Assumptions!$C$45,0) -> 0 | G27: =IF(5=Assumptions!$C$39,Assumptions!$C$10*Assumptions!$C$44+Assumptions!$C$45,0) -> 0 | H27: =IF(6=Assumptions!$C$39,Assumptions!$C$10*Assumptions!$C$44+Assumptions!$C$45,0) -> 0 | I27: =IF(7=Assumptions!$C$39,Assumptions!$C$10*Assumptions!$C$44+Assumptions!$C$45,0) -> 0 | J27: =IF(8=Assumptions!$C$39,Assumptions!$C$10*Assumptions!$C$44+Assumptions!$C$45,0) -> 0 | K27: =IF(9=Assumptions!$C$39,Assumptions!$C$10*Assumptions!$C$44+Assumptions!$C$45,0) -> 0 | L27: =IF(10=Assumptions!$C$39,Assumptions!$C$10*Assumptions!$C$44+Assumptions!$C$45,0) -> 0 | M27: =IF(11=Assumptions!$C$39,Assumptions!$C$10*Assumptions!$C$44+Assumptions!$C$45,0) -> 0 | N27: =IF(12=Assumptions!$C$39,Assumptions!$C$10*Assumptions!$C$44+Assumptions!$C$45,0) -> 0 | O27: =IF(13=Assumptions!$C$39,Assumptions!$C$10*Assumptions!$C$44+Assumptions!$C$45,0) -> 0 | P27: =IF(14=Assumptions!$C$39,Assumptions!$C$10*Assumptions!$C$44+Assumptions!$C$45,0) -> 0 | Q27: =IF(15=Assumptions!$C$39,Assumptions!$C$10*Assumptions!$C$44+Assumptions!$C$45,0) -> 0 | R27: =IF(16=Assumptions!$C$39,Assumptions!$C$10*Assumptions!$C$44+Assumptions!$C$45,0) -> 0 | S27: =IF(17=Assumptions!$C$39,Assumptions!$C$10*Assumptions!$C$44+Assumptions!$C$45,0) -> 0 | T27: =IF(18=Assumptions!$C$39,Assumptions!$C$10*Assumptions!$C$44+Assumptions!$C$45,0) -> 0 | U27: =IF(19=Assumptions!$C$39,Assumptions!$C$10*Assumptions!$C$44+Assumptions!$C$45,0) -> 0 | V27: =IF(20=Assumptions!$C$39,Assumptions!$C$10*Assumptions!$C$44+Assumptions!$C$45,0) -> 0
B28: Partner 2 Titan | C28: =IF(1=Assumptions!$D$39,Assumptions!$D$10*Assumptions!$C$44+Assumptions!$C$45,0) -> 0 | D28: =IF(2=Assumptions!$D$39,Assumptions!$D$10*Assumptions!$C$44+Assumptions!$C$45,0) -> 0 | E28: =IF(3=Assumptions!$D$39,Assumptions!$D$10*Assumptions!$C$44+Assumptions!$C$45,0) -> 195000 | F28: =IF(4=Assumptions!$D$39,Assumptions!$D$10*Assumptions!$C$44+Assumptions!$C$45,0) -> 0 | G28: =IF(5=Assumptions!$D$39,Assumptions!$D$10*Assumptions!$C$44+Assumptions!$C$45,0) -> 0 | H28: =IF(6=Assumptions!$D$39,Assumptions!$D$10*Assumptions!$C$44+Assumptions!$C$45,0) -> 0 | I28: =IF(7=Assumptions!$D$39,Assumptions!$D$10*Assumptions!$C$44+Assumptions!$C$45,0) -> 0 | J28: =IF(8=Assumptions!$D$39,Assumptions!$D$10*Assumptions!$C$44+Assumptions!$C$45,0) -> 0 | K28: =IF(9=Assumptions!$D$39,Assumptions!$D$10*Assumptions!$C$44+Assumptions!$C$45,0) -> 0 | L28: =IF(10=Assumptions!$D$39,Assumptions!$D$10*Assumptions!$C$44+Assumptions!$C$45,0) -> 0 | M28: =IF(11=Assumptions!$D$39,Assumptions!$D$10*Assumptions!$C$44+Assumptions!$C$45,0) -> 0 | N28: =IF(12=Assumptions!$D$39,Assumptions!$D$10*Assumptions!$C$44+Assumptions!$C$45,0) -> 0 | O28: =IF(13=Assumptions!$D$39,Assumptions!$D$10*Assumptions!$C$44+Assumptions!$C$45,0) -> 0 | P28: =IF(14=Assumptions!$D$39,Assumptions!$D$10*Assumptions!$C$44+Assumptions!$C$45,0) -> 0 | Q28: =IF(15=Assumptions!$D$39,Assumptions!$D$10*Assumptions!$C$44+Assumptions!$C$45,0) -> 0 | R28: =IF(16=Assumptions!$D$39,Assumptions!$D$10*Assumptions!$C$44+Assumptions!$C$45,0) -> 0 | S28: =IF(17=Assumptions!$D$39,Assumptions!$D$10*Assumptions!$C$44+Assumptions!$C$45,0) -> 0 | T28: =IF(18=Assumptions!$D$39,Assumptions!$D$10*Assumptions!$C$44+Assumptions!$C$45,0) -> 0 | U28: =IF(19=Assumptions!$D$39,Assumptions!$D$10*Assumptions!$C$44+Assumptions!$C$45,0) -> 0 | V28: =IF(20=Assumptions!$D$39,Assumptions!$D$10*Assumptions!$C$44+Assumptions!$C$45,0) -> 0
B29: Partner 3 Apex | C29: =IF(1=Assumptions!$E$39,Assumptions!$E$10*Assumptions!$C$44+Assumptions!$C$45,0) -> 0 | D29: =IF(2=Assumptions!$E$39,Assumptions!$E$10*Assumptions!$C$44+Assumptions!$C$45,0) -> 0 | E29: =IF(3=Assumptions!$E$39,Assumptions!$E$10*Assumptions!$C$44+Assumptions!$C$45,0) -> 0 | F29: =IF(4=Assumptions!$E$39,Assumptions!$E$10*Assumptions!$C$44+Assumptions!$C$45,0) -> 225000 | G29: =IF(5=Assumptions!$E$39,Assumptions!$E$10*Assumptions!$C$44+Assumptions!$C$45,0) -> 0 | H29: =IF(6=Assumptions!$E$39,Assumptions!$E$10*Assumptions!$C$44+Assumptions!$C$45,0) -> 0 | I29: =IF(7=Assumptions!$E$39,Assumptions!$E$10*Assumptions!$C$44+Assumptions!$C$45,0) -> 0 | J29: =IF(8=Assumptions!$E$39,Assumptions!$E$10*Assumptions!$C$44+Assumptions!$C$45,0) -> 0 | K29: =IF(9=Assumptions!$E$39,Assumptions!$E$10*Assumptions!$C$44+Assumptions!$C$45,0) -> 0 | L29: =IF(10=Assumptions!$E$39,Assumptions!$E$10*Assumptions!$C$44+Assumptions!$C$45,0) -> 0 | M29: =IF(11=Assumptions!$E$39,Assumptions!$E$10*Assumptions!$C$44+Assumptions!$C$45,0) -> 0 | N29: =IF(12=Assumptions!$E$39,Assumptions!$E$10*Assumptions!$C$44+Assumptions!$C$45,0) -> 0 | O29: =IF(13=Assumptions!$E$39,Assumptions!$E$10*Assumptions!$C$44+Assumptions!$C$45,0) -> 0 | P29: =IF(14=Assumptions!$E$39,Assumptions!$E$10*Assumptions!$C$44+Assumptions!$C$45,0) -> 0 | Q29: =IF(15=Assumptions!$E$39,Assumptions!$E$10*Assumptions!$C$44+Assumptions!$C$45,0) -> 0 | R29: =IF(16=Assumptions!$E$39,Assumptions!$E$10*Assumptions!$C$44+Assumptions!$C$45,0) -> 0 | S29: =IF(17=Assumptions!$E$39,Assumptions!$E$10*Assumptions!$C$44+Assumptions!$C$45,0) -> 0 | T29: =IF(18=Assumptions!$E$39,Assumptions!$E$10*Assumptions!$C$44+Assumptions!$C$45,0) -> 0 | U29: =IF(19=Assumptions!$E$39,Assumptions!$E$10*Assumptions!$C$44+Assumptions!$C$45,0) -> 0 | V29: =IF(20=Assumptions!$E$39,Assumptions!$E$10*Assumptions!$C$44+Assumptions!$C$45,0) -> 0
B30: Partner 4 Vanguard | C30: =IF(1=Assumptions!$F$39,Assumptions!$F$10*Assumptions!$C$44+Assumptions!$C$45,0) -> 0 | D30: =IF(2=Assumptions!$F$39,Assumptions!$F$10*Assumptions!$C$44+Assumptions!$C$45,0) -> 0 | E30: =IF(3=Assumptions!$F$39,Assumptions!$F$10*Assumptions!$C$44+Assumptions!$C$45,0) -> 0 | F30: =IF(4=Assumptions!$F$39,Assumptions!$F$10*Assumptions!$C$44+Assumptions!$C$45,0) -> 0 | G30: =IF(5=Assumptions!$F$39,Assumptions!$F$10*Assumptions!$C$44+Assumptions!$C$45,0) -> 165000 | H30: =IF(6=Assumptions!$F$39,Assumptions!$F$10*Assumptions!$C$44+Assumptions!$C$45,0) -> 0 | I30: =IF(7=Assumptions!$F$39,Assumptions!$F$10*Assumptions!$C$44+Assumptions!$C$45,0) -> 0 | J30: =IF(8=Assumptions!$F$39,Assumptions!$F$10*Assumptions!$C$44+Assumptions!$C$45,0) -> 0 | K30: =IF(9=Assumptions!$F$39,Assumptions!$F$10*Assumptions!$C$44+Assumptions!$C$45,0) -> 0 | L30: =IF(10=Assumptions!$F$39,Assumptions!$F$10*Assumptions!$C$44+Assumptions!$C$45,0) -> 0 | M30: =IF(11=Assumptions!$F$39,Assumptions!$F$10*Assumptions!$C$44+Assumptions!$C$45,0) -> 0 | N30: =IF(12=Assumptions!$F$39,Assumptions!$F$10*Assumptions!$C$44+Assumptions!$C$45,0) -> 0 | O30: =IF(13=Assumptions!$F$39,Assumptions!$F$10*Assumptions!$C$44+Assumptions!$C$45,0) -> 0 | P30: =IF(14=Assumptions!$F$39,Assumptions!$F$10*Assumptions!$C$44+Assumptions!$C$45,0) -> 0 | Q30: =IF(15=Assumptions!$F$39,Assumptions!$F$10*Assumptions!$C$44+Assumptions!$C$45,0) -> 0 | R30: =IF(16=Assumptions!$F$39,Assumptions!$F$10*Assumptions!$C$44+Assumptions!$C$45,0) -> 0 | S30: =IF(17=Assumptions!$F$39,Assumptions!$F$10*Assumptions!$C$44+Assumptions!$C$45,0) -> 0 | T30: =IF(18=Assumptions!$F$39,Assumptions!$F$10*Assumptions!$C$44+Assumptions!$C$45,0) -> 0 | U30: =IF(19=Assumptions!$F$39,Assumptions!$F$10*Assumptions!$C$44+Assumptions!$C$45,0) -> 0 | V30: =IF(20=Assumptions!$F$39,Assumptions!$F$10*Assumptions!$C$44+Assumptions!$C$45,0) -> 0
B31: Partner 5 Nimble | C31: =IF(1=Assumptions!$G$39,Assumptions!$G$10*Assumptions!$C$44+Assumptions!$C$45,0) -> 0 | D31: =IF(2=Assumptions!$G$39,Assumptions!$G$10*Assumptions!$C$44+Assumptions!$C$45,0) -> 0 | E31: =IF(3=Assumptions!$G$39,Assumptions!$G$10*Assumptions!$C$44+Assumptions!$C$45,0) -> 0 | F31: =IF(4=Assumptions!$G$39,Assumptions!$G$10*Assumptions!$C$44+Assumptions!$C$45,0) -> 0 | G31: =IF(5=Assumptions!$G$39,Assumptions!$G$10*Assumptions!$C$44+Assumptions!$C$45,0) -> 0 | H31: =IF(6=Assumptions!$G$39,Assumptions!$G$10*Assumptions!$C$44+Assumptions!$C$45,0) -> 135000 | I31: =IF(7=Assumptions!$G$39,Assumptions!$G$10*Assumptions!$C$44+Assumptions!$C$45,0) -> 0 | J31: =IF(8=Assumptions!$G$39,Assumptions!$G$10*Assumptions!$C$44+Assumptions!$C$45,0) -> 0 | K31: =IF(9=Assumptions!$G$39,Assumptions!$G$10*Assumptions!$C$44+Assumptions!$C$45,0) -> 0 | L31: =IF(10=Assumptions!$G$39,Assumptions!$G$10*Assumptions!$C$44+Assumptions!$C$45,0) -> 0 | M31: =IF(11=Assumptions!$G$39,Assumptions!$G$10*Assumptions!$C$44+Assumptions!$C$45,0) -> 0 | N31: =IF(12=Assumptions!$G$39,Assumptions!$G$10*Assumptions!$C$44+Assumptions!$C$45,0) -> 0 | O31: =IF(13=Assumptions!$G$39,Assumptions!$G$10*Assumptions!$C$44+Assumptions!$C$45,0) -> 0 | P31: =IF(14=Assumptions!$G$39,Assumptions!$G$10*Assumptions!$C$44+Assumptions!$C$45,0) -> 0 | Q31: =IF(15=Assumptions!$G$39,Assumptions!$G$10*Assumptions!$C$44+Assumptions!$C$45,0) -> 0 | R31: =IF(16=Assumptions!$G$39,Assumptions!$G$10*Assumptions!$C$44+Assumptions!$C$45,0) -> 0 | S31: =IF(17=Assumptions!$G$39,Assumptions!$G$10*Assumptions!$C$44+Assumptions!$C$45,0) -> 0 | T31: =IF(18=Assumptions!$G$39,Assumptions!$G$10*Assumptions!$C$44+Assumptions!$C$45,0) -> 0 | U31: =IF(19=Assumptions!$G$39,Assumptions!$G$10*Assumptions!$C$44+Assumptions!$C$45,0) -> 0 | V31: =IF(20=Assumptions!$G$39,Assumptions!$G$10*Assumptions!$C$44+Assumptions!$C$45,0) -> 0
B33: Total Non-GAAP Impl + Consulting | C33: =C27+C28+C29+C30+C31 -> 0 | D33: =D27+D28+D29+D30+D31 -> 255000 | E33: =E27+E28+E29+E30+E31 -> 195000 | F33: =F27+F28+F29+F30+F31 -> 225000 | G33: =G27+G28+G29+G30+G31 -> 165000 | H33: =H27+H28+H29+H30+H31 -> 135000 | I33: =I27+I28+I29+I30+I31 -> 0 | J33: =J27+J28+J29+J30+J31 -> 0 | ... V33: =V27+V28+V29+V30+V31 -> 0
B35: NON-GAAP SUBSCRIPTION REVENUE
B36: Partner 1 Atlas | C36: =IF(AND(C7>0,1<Assumptions!$C$41),C7*Assumptions!$C$18/4,0) -> 0 | D36: =IF(AND(D7>0,2<Assumptions!$C$41),D7*Assumptions!$C$18/4,0) -> 0 | E36: =IF(AND(E7>0,3<Assumptions!$C$41),E7*Assumptions!$C$18/4,0) -> 0 | F36: =IF(AND(F7>0,4<Assumptions!$C$41),F7*Assumptions!$C$18/4,0) -> 63750 | G36: =IF(AND(G7>0,5<Assumptions!$C$41),G7*Assumptions!$C$18/4,0) -> 127500 | H36: =IF(AND(H7>0,6<Assumptions!$C$41),H7*Assumptions!$C$18/4,0) -> 127500 | I36: =IF(AND(I7>0,7<Assumptions!$C$41),I7*Assumptions!$C$18/4,0) -> 127500 | J36: =IF(AND(J7>0,8<Assumptions!$C$41),J7*Assumptions!$C$18/4,0) -> 127500 | K36: =IF(AND(K7>0,9<Assumptions!$C$41),K7*Assumptions!$C$18/4,0) -> 127500 | L36: =IF(AND(L7>0,10<Assumptions!$C$41),L7*Assumptions!$C$18/4,0) -> 0 | M36: =IF(AND(M7>0,11<Assumptions!$C$41),M7*Assumptions!$C$18/4,0) -> 0 | N36: =IF(AND(N7>0,12<Assumptions!$C$41),N7*Assumptions!$C$18/4,0) -> 0 | O36: =IF(AND(O7>0,13<Assumptions!$C$41),O7*Assumptions!$C$18/4,0) -> 0 | P36: =IF(AND(P7>0,14<Assumptions!$C$41),P7*Assumptions!$C$18/4,0) -> 0 | Q36: =IF(AND(Q7>0,15<Assumptions!$C$41),Q7*Assumptions!$C$18/4,0) -> 0 | R36: =IF(AND(R7>0,16<Assumptions!$C$41),R7*Assumptions!$C$18/4,0) -> 0 | S36: =IF(AND(S7>0,17<Assumptions!$C$41),S7*Assumptions!$C$18/4,0) -> 0 | T36: =IF(AND(T7>0,18<Assumptions!$C$41),T7*Assumptions!$C$18/4,0) -> 0 | U36: =IF(AND(U7>0,19<Assumptions!$C$41),U7*Assumptions!$C$18/4,0) -> 0 | V36: =IF(AND(V7>0,20<Assumptions!$C$41),V7*Assumptions!$C$18/4,0) -> 0
B37: Partner 2 Titan | C37: =IF(AND(C8>0,1<Assumptions!$D$41),C8*Assumptions!$C$18/4,0) -> 0 | D37: =IF(AND(D8>0,2<Assumptions!$D$41),D8*Assumptions!$C$18/4,0) -> 0 | E37: =IF(AND(E8>0,3<Assumptions!$D$41),E8*Assumptions!$C$18/4,0) -> 0 | F37: =IF(AND(F8>0,4<Assumptions!$D$41),F8*Assumptions!$C$18/4,0) -> 0 | G37: =IF(AND(G8>0,5<Assumptions!$D$41),G8*Assumptions!$C$18/4,0) -> 42500 | H37: =IF(AND(H8>0,6<Assumptions!$D$41),H8*Assumptions!$C$18/4,0) -> 85000 | I37: =IF(AND(I8>0,7<Assumptions!$D$41),I8*Assumptions!$C$18/4,0) -> 85000 | J37: =IF(AND(J8>0,8<Assumptions!$D$41),J8*Assumptions!$C$18/4,0) -> 85000 | K37: =IF(AND(K8>0,9<Assumptions!$D$41),K8*Assumptions!$C$18/4,0) -> 0 | L37: =IF(AND(L8>0,10<Assumptions!$D$41),L8*Assumptions!$C$18/4,0) -> 0 | M37: =IF(AND(M8>0,11<Assumptions!$D$41),M8*Assumptions!$C$18/4,0) -> 0 | N37: =IF(AND(N8>0,12<Assumptions!$D$41),N8*Assumptions!$C$18/4,0) -> 0 | O37: =IF(AND(O8>0,13<Assumptions!$D$41),O8*Assumptions!$C$18/4,0) -> 0 | P37: =IF(AND(P8>0,14<Assumptions!$D$41),P8*Assumptions!$C$18/4,0) -> 0 | Q37: =IF(AND(Q8>0,15<Assumptions!$D$41),Q8*Assumptions!$C$18/4,0) -> 0 | R37: =IF(AND(R8>0,16<Assumptions!$D$41),R8*Assumptions!$C$18/4,0) -> 0 | S37: =IF(AND(S8>0,17<Assumptions!$D$41),S8*Assumptions!$C$18/4,0) -> 0 | T37: =IF(AND(T8>0,18<Assumptions!$D$41),T8*Assumptions!$C$18/4,0) -> 0 | U37: =IF(AND(U8>0,19<Assumptions!$D$41),U8*Assumptions!$C$18/4,0) -> 0 | V37: =IF(AND(V8>0,20<Assumptions!$D$41),V8*Assumptions!$C$18/4,0) -> 0
B38: Partner 3 Apex | C38: =IF(AND(C9>0,1<Assumptions!$E$41),C9*Assumptions!$C$18/4,0) -> 0 | D38: =IF(AND(D9>0,2<Assumptions!$E$41),D9*Assumptions!$C$18/4,0) -> 0 | E38: =IF(AND(E9>0,3<Assumptions!$E$41),E9*Assumptions!$C$18/4,0) -> 0 | F38: =IF(AND(F9>0,4<Assumptions!$E$41),F9*Assumptions!$C$18/4,0) -> 0 | G38: =IF(AND(G9>0,5<Assumptions!$E$41),G9*Assumptions!$C$18/4,0) -> 0 | H38: =IF(AND(H9>0,6<Assumptions!$E$41),H9*Assumptions!$C$18/4,0) -> 42500 | I38: =IF(AND(I9>0,7<Assumptions!$E$41),I9*Assumptions!$C$18/4,0) -> 106250 | J38: =IF(AND(J9>0,8<Assumptions!$E$41),J9*Assumptions!$C$18/4,0) -> 106250 | K38: =IF(AND(K9>0,9<Assumptions!$E$41),K9*Assumptions!$C$18/4,0) -> 106250 | L38: =IF(AND(L9>0,10<Assumptions!$E$41),L9*Assumptions!$C$18/4,0) -> 0 | M38: =IF(AND(M9>0,11<Assumptions!$E$41),M9*Assumptions!$C$18/4,0) -> 0 | N38: =IF(AND(N9>0,12<Assumptions!$E$41),N9*Assumptions!$C$18/4,0) -> 0 | O38: =IF(AND(O9>0,13<Assumptions!$E$41),O9*Assumptions!$C$18/4,0) -> 0 | P38: =IF(AND(P9>0,14<Assumptions!$E$41),P9*Assumptions!$C$18/4,0) -> 0 | Q38: =IF(AND(Q9>0,15<Assumptions!$E$41),Q9*Assumptions!$C$18/4,0) -> 0 | R38: =IF(AND(R9>0,16<Assumptions!$E$41),R9*Assumptions!$C$18/4,0) -> 0 | S38: =IF(AND(S9>0,17<Assumptions!$E$41),S9*Assumptions!$C$18/4,0) -> 0 | T38: =IF(AND(T9>0,18<Assumptions!$E$41),T9*Assumptions!$C$18/4,0) -> 0 | U38: =IF(AND(U9>0,19<Assumptions!$E$41),U9*Assumptions!$C$18/4,0) -> 0 | V38: =IF(AND(V9>0,20<Assumptions!$E$41),V9*Assumptions!$C$18/4,0) -> 0
B39: Partner 4 Vanguard | C39: =IF(AND(C10>0,1<Assumptions!$F$41),C10*Assumptions!$C$18/4,0) -> 0 | D39: =IF(AND(D10>0,2<Assumptions!$F$41),D10*Assumptions!$C$18/4,0) -> 0 | E39: =IF(AND(E10>0,3<Assumptions!$F$41),E10*Assumptions!$C$18/4,0) -> 0 | F39: =IF(AND(F10>0,4<Assumptions!$F$41),F10*Assumptions!$C$18/4,0) -> 0 | G39: =IF(AND(G10>0,5<Assumptions!$F$41),G10*Assumptions!$C$18/4,0) -> 0 | H39: =IF(AND(H10>0,6<Assumptions!$F$41),H10*Assumptions!$C$18/4,0) -> 0 | I39: =IF(AND(I10>0,7<Assumptions!$F$41),I10*Assumptions!$C$18/4,0) -> 42500 | J39: =IF(AND(J10>0,8<Assumptions!$F$41),J10*Assumptions!$C$18/4,0) -> 63750 | K39: =IF(AND(K10>0,9<Assumptions!$F$41),K10*Assumptions!$C$18/4,0) -> 63750 | L39: =IF(AND(L10>0,10<Assumptions!$F$41),L10*Assumptions!$C$18/4,0) -> 63750 | M39: =IF(AND(M10>0,11<Assumptions!$F$41),M10*Assumptions!$C$18/4,0) -> 0 | N39: =IF(AND(N10>0,12<Assumptions!$F$41),N10*Assumptions!$C$18/4,0) -> 0 | O39: =IF(AND(O10>0,13<Assumptions!$F$41),O10*Assumptions!$C$18/4,0) -> 0 | P39: =IF(AND(P10>0,14<Assumptions!$F$41),P10*Assumptions!$C$18/4,0) -> 0 | Q39: =IF(AND(Q10>0,15<Assumptions!$F$41),Q10*Assumptions!$C$18/4,0) -> 0 | R39: =IF(AND(R10>0,16<Assumptions!$F$41),R10*Assumptions!$C$18/4,0) -> 0 | S39: =IF(AND(S10>0,17<Assumptions!$F$41),S10*Assumptions!$C$18/4,0) -> 0 | T39: =IF(AND(T10>0,18<Assumptions!$F$41),T10*Assumptions!$C$18/4,0) -> 0 | U39: =IF(AND(U10>0,19<Assumptions!$F$41),U10*Assumptions!$C$18/4,0) -> 0 | V39: =IF(AND(V10>0,20<Assumptions!$F$41),V10*Assumptions!$C$18/4,0) -> 0
B40: Partner 5 Nimble | C40: =IF(AND(C11>0,1<Assumptions!$G$41),C11*Assumptions!$C$18/4,0) -> 0 | D40: =IF(AND(D11>0,2<Assumptions!$G$41),D11*Assumptions!$C$18/4,0) -> 0 | E40: =IF(AND(E11>0,3<Assumptions!$G$41),E11*Assumptions!$C$18/4,0) -> 0 | F40: =IF(AND(F11>0,4<Assumptions!$G$41),F11*Assumptions!$C$18/4,0) -> 0 | G40: =IF(AND(G11>0,5<Assumptions!$G$41),G11*Assumptions!$C$18/4,0) -> 0 | H40: =IF(AND(H11>0,6<Assumptions!$G$41),H11*Assumptions!$C$18/4,0) -> 0 | I40: =IF(AND(I11>0,7<Assumptions!$G$41),I11*Assumptions!$C$18/4,0) -> 0 | J40: =IF(AND(J11>0,8<Assumptions!$G$41),J11*Assumptions!$C$18/4,0) -> 42500 | K40: =IF(AND(K11>0,9<Assumptions!$G$41),K11*Assumptions!$C$18/4,0) -> 42500 | L40: =IF(AND(L11>0,10<Assumptions!$G$41),L11*Assumptions!$C$18/4,0) -> 42500 | M40: =IF(AND(M11>0,11<Assumptions!$G$41),M11*Assumptions!$C$18/4,0) -> 42500 | N40: =IF(AND(N11>0,12<Assumptions!$G$41),N11*Assumptions!$C$18/4,0) -> 0 | O40: =IF(AND(O11>0,13<Assumptions!$G$41),O11*Assumptions!$C$18/4,0) -> 0 | P40: =IF(AND(P11>0,14<Assumptions!$G$41),P11*Assumptions!$C$18/4,0) -> 0 | Q40: =IF(AND(Q11>0,15<Assumptions!$G$41),Q11*Assumptions!$C$18/4,0) -> 0 | R40: =IF(AND(R11>0,16<Assumptions!$G$41),R11*Assumptions!$C$18/4,0) -> 0 | S40: =IF(AND(S11>0,17<Assumptions!$G$41),S11*Assumptions!$C$18/4,0) -> 0 | T40: =IF(AND(T11>0,18<Assumptions!$G$41),T11*Assumptions!$C$18/4,0) -> 0 | U40: =IF(AND(U11>0,19<Assumptions!$G$41),U11*Assumptions!$C$18/4,0) -> 0 | V40: =IF(AND(V11>0,20<Assumptions!$G$41),V11*Assumptions!$C$18/4,0) -> 0
B42: Total Non-GAAP Subscription | C42: =C36+C37+C38+C39+C40 -> 0 | D42: =D36+D37+D38+D39+D40 -> 0 | E42: =E36+E37+E38+E39+E40 -> 0 | F42: =F36+F37+F38+F39+F40 -> 63750 | G42: =G36+G37+G38+G39+G40 -> 170000 | H42: =H36+H37+H38+H39+H40 -> 255000 | I42: =I36+I37+I38+I39+I40 -> 361250 | J42: =J36+J37+J38+J39+J40 -> 425000 | ... V42: =V36+V37+V38+V39+V40 -> 0
B44: Zone Licensing Fee
B45: Partner 1 Atlas | C45: =IF(1>=Assumptions!$C$41,Assumptions!$C$15/4,0) -> 0 | D45: =IF(2>=Assumptions!$C$41,Assumptions!$C$15/4,0) -> 0 | E45: =IF(3>=Assumptions!$C$41,Assumptions!$C$15/4,0) -> 0 | F45: =IF(4>=Assumptions!$C$41,Assumptions!$C$15/4,0) -> 0 | G45: =IF(5>=Assumptions!$C$41,Assumptions!$C$15/4,0) -> 0 | H45: =IF(6>=Assumptions!$C$41,Assumptions!$C$15/4,0) -> 0 | I45: =IF(7>=Assumptions!$C$41,Assumptions!$C$15/4,0) -> 0 | J45: =IF(8>=Assumptions!$C$41,Assumptions!$C$15/4,0) -> 0 | K45: =IF(9>=Assumptions!$C$41,Assumptions!$C$15/4,0) -> 0 | L45: =IF(10>=Assumptions!$C$41,Assumptions!$C$15/4,0) -> 127500 | M45: =IF(11>=Assumptions!$C$41,Assumptions!$C$15/4,0) -> 127500 | N45: =IF(12>=Assumptions!$C$41,Assumptions!$C$15/4,0) -> 127500 | O45: =IF(13>=Assumptions!$C$41,Assumptions!$C$15/4,0) -> 127500 | P45: =IF(14>=Assumptions!$C$41,Assumptions!$C$15/4,0) -> 127500 | Q45: =IF(15>=Assumptions!$C$41,Assumptions!$C$15/4,0) -> 127500 | R45: =IF(16>=Assumptions!$C$41,Assumptions!$C$15/4,0) -> 127500 | S45: =IF(17>=Assumptions!$C$41,Assumptions!$C$15/4,0) -> 127500 | T45: =IF(18>=Assumptions!$C$41,Assumptions!$C$15/4,0) -> 127500 | U45: =IF(19>=Assumptions!$C$41,Assumptions!$C$15/4,0) -> 127500 | V45: =IF(20>=Assumptions!$C$41,Assumptions!$C$15/4,0) -> 127500
B46: Partner 2 Titan | C46: =IF(1>=Assumptions!$D$41,Assumptions!$D$15/4,0) -> 0 | D46: =IF(2>=Assumptions!$D$41,Assumptions!$D$15/4,0) -> 0 | E46: =IF(3>=Assumptions!$D$41,Assumptions!$D$15/4,0) -> 0 | F46: =IF(4>=Assumptions!$D$41,Assumptions!$D$15/4,0) -> 0 | G46: =IF(5>=Assumptions!$D$41,Assumptions!$D$15/4,0) -> 0 | H46: =IF(6>=Assumptions!$D$41,Assumptions!$D$15/4,0) -> 0 | I46: =IF(7>=Assumptions!$D$41,Assumptions!$D$15/4,0) -> 0 | J46: =IF(8>=Assumptions!$D$41,Assumptions!$D$15/4,0) -> 0 | K46: =IF(9>=Assumptions!$D$41,Assumptions!$D$15/4,0) -> 85000 | L46: =IF(10>=Assumptions!$D$41,Assumptions!$D$15/4,0) -> 85000 | M46: =IF(11>=Assumptions!$D$41,Assumptions!$D$15/4,0) -> 85000 | N46: =IF(12>=Assumptions!$D$41,Assumptions!$D$15/4,0) -> 85000 | O46: =IF(13>=Assumptions!$D$41,Assumptions!$D$15/4,0) -> 85000 | P46: =IF(14>=Assumptions!$D$41,Assumptions!$D$15/4,0) -> 85000 | Q46: =IF(15>=Assumptions!$D$41,Assumptions!$D$15/4,0) -> 85000 | R46: =IF(16>=Assumptions!$D$41,Assumptions!$D$15/4,0) -> 85000 | S46: =IF(17>=Assumptions!$D$41,Assumptions!$D$15/4,0) -> 85000 | T46: =IF(18>=Assumptions!$D$41,Assumptions!$D$15/4,0) -> 85000 | U46: =IF(19>=Assumptions!$D$41,Assumptions!$D$15/4,0) -> 85000 | V46: =IF(20>=Assumptions!$D$41,Assumptions!$D$15/4,0) -> 85000
B47: Partner 3 Apex | C47: =IF(1>=Assumptions!$E$41,Assumptions!$E$15/4,0) -> 0 | D47: =IF(2>=Assumptions!$E$41,Assumptions!$E$15/4,0) -> 0 | E47: =IF(3>=Assumptions!$E$41,Assumptions!$E$15/4,0) -> 0 | F47: =IF(4>=Assumptions!$E$41,Assumptions!$E$15/4,0) -> 0 | G47: =IF(5>=Assumptions!$E$41,Assumptions!$E$15/4,0) -> 0 | H47: =IF(6>=Assumptions!$E$41,Assumptions!$E$15/4,0) -> 0 | I47: =IF(7>=Assumptions!$E$41,Assumptions!$E$15/4,0) -> 0 | J47: =IF(8>=Assumptions!$E$41,Assumptions!$E$15/4,0) -> 0 | K47: =IF(9>=Assumptions!$E$41,Assumptions!$E$15/4,0) -> 0 | L47: =IF(10>=Assumptions!$E$41,Assumptions!$E$15/4,0) -> 106250 | M47: =IF(11>=Assumptions!$E$41,Assumptions!$E$15/4,0) -> 106250 | N47: =IF(12>=Assumptions!$E$41,Assumptions!$E$15/4,0) -> 106250 | O47: =IF(13>=Assumptions!$E$41,Assumptions!$E$15/4,0) -> 106250 | P47: =IF(14>=Assumptions!$E$41,Assumptions!$E$15/4,0) -> 106250 | Q47: =IF(15>=Assumptions!$E$41,Assumptions!$E$15/4,0) -> 106250 | R47: =IF(16>=Assumptions!$E$41,Assumptions!$E$15/4,0) -> 106250 | S47: =IF(17>=Assumptions!$E$41,Assumptions!$E$15/4,0) -> 106250 | T47: =IF(18>=Assumptions!$E$41,Assumptions!$E$15/4,0) -> 106250 | U47: =IF(19>=Assumptions!$E$41,Assumptions!$E$15/4,0) -> 106250 | V47: =IF(20>=Assumptions!$E$41,Assumptions!$E$15/4,0) -> 106250
B48: Partner 4 Vanguard | C48: =IF(1>=Assumptions!$F$41,Assumptions!$F$15/4,0) -> 0 | D48: =IF(2>=Assumptions!$F$41,Assumptions!$F$15/4,0) -> 0 | E48: =IF(3>=Assumptions!$F$41,Assumptions!$F$15/4,0) -> 0 | F48: =IF(4>=Assumptions!$F$41,Assumptions!$F$15/4,0) -> 0 | G48: =IF(5>=Assumptions!$F$41,Assumptions!$F$15/4,0) -> 0 | H48: =IF(6>=Assumptions!$F$41,Assumptions!$F$15/4,0) -> 0 | I48: =IF(7>=Assumptions!$F$41,Assumptions!$F$15/4,0) -> 0 | J48: =IF(8>=Assumptions!$F$41,Assumptions!$F$15/4,0) -> 0 | K48: =IF(9>=Assumptions!$F$41,Assumptions!$F$15/4,0) -> 0 | L48: =IF(10>=Assumptions!$F$41,Assumptions!$F$15/4,0) -> 0 | M48: =IF(11>=Assumptions!$F$41,Assumptions!$F$15/4,0) -> 63750 | N48: =IF(12>=Assumptions!$F$41,Assumptions!$F$15/4,0) -> 63750 | O48: =IF(13>=Assumptions!$F$41,Assumptions!$F$15/4,0) -> 63750 | P48: =IF(14>=Assumptions!$F$41,Assumptions!$F$15/4,0) -> 63750 | Q48: =IF(15>=Assumptions!$F$41,Assumptions!$F$15/4,0) -> 63750 | R48: =IF(16>=Assumptions!$F$41,Assumptions!$F$15/4,0) -> 63750 | S48: =IF(17>=Assumptions!$F$41,Assumptions!$F$15/4,0) -> 63750 | T48: =IF(18>=Assumptions!$F$41,Assumptions!$F$15/4,0) -> 63750 | U48: =IF(19>=Assumptions!$F$41,Assumptions!$F$15/4,0) -> 63750 | V48: =IF(20>=Assumptions!$F$41,Assumptions!$F$15/4,0) -> 63750
B49: Partner 5 Nimble | C49: =IF(1>=Assumptions!$G$41,Assumptions!$G$15/4,0) -> 0 | D49: =IF(2>=Assumptions!$G$41,Assumptions!$G$15/4,0) -> 0 | E49: =IF(3>=Assumptions!$G$41,Assumptions!$G$15/4,0) -> 0 | F49: =IF(4>=Assumptions!$G$41,Assumptions!$G$15/4,0) -> 0 | G49: =IF(5>=Assumptions!$G$41,Assumptions!$G$15/4,0) -> 0 | H49: =IF(6>=Assumptions!$G$41,Assumptions!$G$15/4,0) -> 0 | I49: =IF(7>=Assumptions!$G$41,Assumptions!$G$15/4,0) -> 0 | J49: =IF(8>=Assumptions!$G$41,Assumptions!$G$15/4,0) -> 0 | K49: =IF(9>=Assumptions!$G$41,Assumptions!$G$15/4,0) -> 0 | L49: =IF(10>=Assumptions!$G$41,Assumptions!$G$15/4,0) -> 0 | M49: =IF(11>=Assumptions!$G$41,Assumptions!$G$15/4,0) -> 0 | N49: =IF(12>=Assumptions!$G$41,Assumptions!$G$15/4,0) -> 42500 | O49: =IF(13>=Assumptions!$G$41,Assumptions!$G$15/4,0) -> 42500 | P49: =IF(14>=Assumptions!$G$41,Assumptions!$G$15/4,0) -> 42500 | Q49: =IF(15>=Assumptions!$G$41,Assumptions!$G$15/4,0) -> 42500 | R49: =IF(16>=Assumptions!$G$41,Assumptions!$G$15/4,0) -> 42500 | S49: =IF(17>=Assumptions!$G$41,Assumptions!$G$15/4,0) -> 42500 | T49: =IF(18>=Assumptions!$G$41,Assumptions!$G$15/4,0) -> 42500 | U49: =IF(19>=Assumptions!$G$41,Assumptions!$G$15/4,0) -> 42500 | V49: =IF(20>=Assumptions!$G$41,Assumptions!$G$15/4,0) -> 42500
B51: Total Licensing | C51: =C45+C46+C47+C48+C49 -> 0 | D51: =D45+D46+D47+D48+D49 -> 0 | E51: =E45+E46+E47+E48+E49 -> 0 | F51: =F45+F46+F47+F48+F49 -> 0 | G51: =G45+G46+G47+G48+G49 -> 0 | H51: =H45+H46+H47+H48+H49 -> 0 | I51: =I45+I46+I47+I48+I49 -> 0 | J51: =J45+J46+J47+J48+J49 -> 0 | ... V51: =V45+V46+V47+V48+V49 -> 425000
B53: Operations Revenue
B54: Autonomous Picking
